Workbook

Sheet Graph
B1: MI250X GCD
A2: Memory throughput (Gio/s) | B2: 1600 | F2: TODO(Etienne M): practical peak? Stream
A3: GCD frequency (GHz) | B3: 1.7
A4: CU per GCD | B4: 110
A5: SIMD lane per wavefront | B5: 64
B6: Scalar | D6: Matrix FMA
B7: Binary64 | C7: Binary32 | D7: Binary64 | E7: Binary32
A8: Flop/CU/clock | B8: 128 | C8: 128 | D8: 256 | E8: 256 | F8: TODO(Etienne M): 128 or 256 ? Binary32 float2 ?
A9: Flop/clock | B9: =B8*$B$4 -> 14080 | C9: =C8*$B$4 -> 14080 | D9: =D8*$B$4 -> 28160 | E9: =E8*$B$4 -> 28160
A10: Peak Flop/s | B10: =B9*$B$3*1000000000 -> 23936000000000 | C10: =C9*$B$3*1000000000 -> 23936000000000 | D10: =D9*$B$3*1000000000 -> 47872000000000 | E10: =E9*$B$3*1000000000 -> 47872000000000 | F10: TODO(Etienne M): practical peak (gemm)
A11: Arithmetic intensity (Flop/octet loaded or stored) | B11: Scalar Gflop/s roofline | D11: Matrix FMA Gflop/s roofline
B12: Scalar Binary64 | C12: Scalar Binary32 | D12: MFMA Binary64 | E12: MFMA Binary32
A13: =1/512 -> 0.001953125 | B13: =MIN($A13*$B$2*1024^3,B$10)/1000000000 -> 3.3554432 | C13: =MIN($A13*$B$2*1024^3,C$10)/1000000000 -> 3.3554432 | D13: =MIN($A13*$B$2*1024^3,D$10)/1000000000 -> 3.3554432 | E13: =MIN($A13*$B$2*1024^3,E$10)/1000000000 -> 3.3554432
A14: =A13*2 -> 0.00390625 | B14: =MIN($A14*$B$2*1024^3,B$10)/1000000000 -> 6.7108864 | C14: =MIN($A14*$B$2*1024^3,C$10)/1000000000 -> 6.7108864 | D14: =MIN($A14*$B$2*1024^3,D$10)/1000000000 -> 6.7108864 | E14: =MIN($A14*$B$2*1024^3,E$10)/1000000000 -> 6.7108864
A15: =A14*2 -> 0.0078125 | B15: =MIN($A15*$B$2*1024^3,B$10)/1000000000 -> 13.421773 | C15: =MIN($A15*$B$2*1024^3,C$10)/1000000000 -> 13.421773 | D15: =MIN($A15*$B$2*1024^3,D$10)/1000000000 -> 13.421773 | E15: =MIN($A15*$B$2*1024^3,E$10)/1000000000 -> 13.421773
A16: =A15*2 -> 0.015625 | B16: =MIN($A16*$B$2*1024^3,B$10)/1000000000 -> 26.843546 | C16: =MIN($A16*$B$2*1024^3,C$10)/1000000000 -> 26.843546 | D16: =MIN($A16*$B$2*1024^3,D$10)/1000000000 -> 26.843546 | E16: =MIN($A16*$B$2*1024^3,E$10)/1000000000 -> 26.843546
A17: =A16*2 -> 0.03125 | B17: =MIN($A17*$B$2*1024^3,B$10)/1000000000 -> 53.687091 | C17: =MIN($A17*$B$2*1024^3,C$10)/1000000000 -> 53.687091 | D17: =MIN($A17*$B$2*1024^3,D$10)/1000000000 -> 53.687091 | E17: =MIN($A17*$B$2*1024^3,E$10)/1000000000 -> 53.687091
A18: =A17*2 -> 0.0625 | B18: =MIN($A18*$B$2*1024^3,B$10)/1000000000 -> 107.37418 | C18: =MIN($A18*$B$2*1024^3,C$10)/1000000000 -> 107.37418 | D18: =MIN($A18*$B$2*1024^3,D$10)/1000000000 -> 107.37418 | E18: =MIN($A18*$B$2*1024^3,E$10)/1000000000 -> 107.37418
A19: =A18*2 -> 0.125 | B19: =MIN($A19*$B$2*1024^3,B$10)/1000000000 -> 214.74836 | C19: =MIN($A19*$B$2*1024^3,C$10)/1000000000 -> 214.74836 | D19: =MIN($A19*$B$2*1024^3,D$10)/1000000000 -> 214.74836 | E19: =MIN($A19*$B$2*1024^3,E$10)/1000000000 -> 214.74836
A20: =A19*2 -> 0.25 | B20: =MIN($A20*$B$2*1024^3,B$10)/1000000000 -> 429.49673 | C20: =MIN($A20*$B$2*1024^3,C$10)/1000000000 -> 429.49673 | D20: =MIN($A20*$B$2*1024^3,D$10)/1000000000 -> 429.49673 | E20: =MIN($A20*$B$2*1024^3,E$10)/1000000000 -> 429.49673
A21: =A20*2 -> 0.5 | B21: =MIN($A21*$B$2*1024^3,B$10)/1000000000 -> 858.99346 | C21: =MIN($A21*$B$2*1024^3,C$10)/1000000000 -> 858.99346 | D21: =MIN($A21*$B$2*1024^3,D$10)/1000000000 -> 858.99346 | E21: =MIN($A21*$B$2*1024^3,E$10)/1000000000 -> 858.99346
A22: =A21*2 -> 1 | B22: =MIN($A22*$B$2*1024^3,B$10)/1000000000 -> 1717.9869 | C22: =MIN($A22*$B$2*1024^3,C$10)/1000000000 -> 1717.9869 | D22: =MIN($A22*$B$2*1024^3,D$10)/1000000000 -> 1717.9869 | E22: =MIN($A22*$B$2*1024^3,E$10)/1000000000 -> 1717.9869
A23: =A22*2 -> 2 | B23: =MIN($A23*$B$2*1024^3,B$10)/1000000000 -> 3435.9738 | C23: =MIN($A23*$B$2*1024^3,C$10)/1000000000 -> 3435.9738 | D23: =MIN($A23*$B$2*1024^3,D$10)/1000000000 -> 3435.9738 | E23: =MIN($A23*$B$2*1024^3,E$10)/1000000000 -> 3435.9738
A24: =A23*2 -> 4 | B24: =MIN($A24*$B$2*1024^3,B$10)/1000000000 -> 6871.9477 | C24: =MIN($A24*$B$2*1024^3,C$10)/1000000000 -> 6871.9477 | D24: =MIN($A24*$B$2*1024^3,D$10)/1000000000 -> 6871.9477 | E24: =MIN($A24*$B$2*1024^3,E$10)/1000000000 -> 6871.9477
A25: =A24*2 -> 8 | B25: =MIN($A25*$B$2*1024^3,B$10)/1000000000 -> 13743.895 | C25: =MIN($A25*$B$2*1024^3,C$10)/1000000000 -> 13743.895 | D25: =MIN($A25*$B$2*1024^3,D$10)/1000000000 -> 13743.895 | E25: =MIN($A25*$B$2*1024^3,E$10)/1000000000 -> 13743.895
... A54: =A53*2 -> 4294967296 | B54: =MIN($A54*$B$2*1024^3,B$10)/1000000000 -> 23936 | C54: =MIN($A54*$B$2*1024^3,C$10)/1000000000 -> 23936 | D54: =MIN($A54*$B$2*1024^3,D$10)/1000000000 -> 47872 | E54: =MIN($A54*$B$2*1024^3,E$10)/1000000000 -> 47872
B55: 80 % Roofline
A56: Arithmetic intensity (Flop/octet loaded or stored) | B56: Scalar Gflop/s roofline | D56: Matrix FMA Gflop/s roofline
B57: 80% Scalar Binary64 | C57: 80% Scalar Binary32 | D57: 80% MFMA Binary64 | E57: 80% MFMA Binary32
A58: =1/512 -> 0.001953125 | B58: =B13*0.8 -> 2.6843546 | C58: =C13*0.8 -> 2.6843546 | D58: =D13*0.8 -> 2.6843546 | E58: =E13*0.8 -> 2.6843546
A59: =A58*2 -> 0.00390625 | B59: =B14*0.8 -> 5.3687091 | C59: =C14*0.8 -> 5.3687091 | D59: =D14*0.8 -> 5.3687091 | E59: =E14*0.8 -> 5.3687091
A60: =A59*2 -> 0.0078125 | B60: =B15*0.8 -> 10.737418 | C60: =C15*0.8 -> 10.737418 | D60: =D15*0.8 -> 10.737418 | E60: =E15*0.8 -> 10.737418
A61: =A60*2 -> 0.015625 | B61: =B16*0.8 -> 21.474836 | C61: =C16*0.8 -> 21.474836 | D61: =D16*0.8 -> 21.474836 | E61: =E16*0.8 -> 21.474836
A62: =A61*2 -> 0.03125 | B62: =B17*0.8 -> 42.949673 | C62: =C17*0.8 -> 42.949673 | D62: =D17*0.8 -> 42.949673 | E62: =E17*0.8 -> 42.949673
A63: =A62*2 -> 0.0625 | B63: =B18*0.8 -> 85.899346 | C63: =C18*0.8 -> 85.899346 | D63: =D18*0.8 -> 85.899346 | E63: =E18*0.8 -> 85.899346
A64: =A63*2 -> 0.125 | B64: =B19*0.8 -> 171.79869 | C64: =C19*0.8 -> 171.79869 | D64: =D19*0.8 -> 171.79869 | E64: =E19*0.8 -> 171.79869
A65: =A64*2 -> 0.25 | B65: =B20*0.8 -> 343.59738 | C65: =C20*0.8 -> 343.59738 | D65: =D20*0.8 -> 343.59738 | E65: =E20*0.8 -> 343.59738
A66: =A65*2 -> 0.5 | B66: =B21*0.8 -> 687.19477 | C66: =C21*0.8 -> 687.19477 | D66: =D21*0.8 -> 687.19477 | E66: =E21*0.8 -> 687.19477
A67: =A66*2 -> 1 | B67: =B22*0.8 -> 1374.3895 | C67: =C22*0.8 -> 1374.3895 | D67: =D22*0.8 -> 1374.3895 | E67: =E22*0.8 -> 1374.3895
A68: =A67*2 -> 2 | B68: =B23*0.8 -> 2748.7791 | C68: =C23*0.8 -> 2748.7791 | D68: =D23*0.8 -> 2748.7791 | E68: =E23*0.8 -> 2748.7791
...

Sheet Process kernel profile data
B1: Binary64 kernels | H1: Binary32 kernels
B2: Flop | C2: Octet | D2: Duration (s) | E2: GFlop/s | F2: Flop/octet | G2: Octet/Flop | H2: Flop | I2: Octet | J2: Duration (s) | K2: GFlop/s | L2: Flop/octet | M2: Octet/Flop
B3: =Graph!$B$5*(SUM('Kernel profile B64'!$V10:$W10,'Kernel profile B64'!$Y10)+2*'Kernel profile B64'!$X10)+'Kernel profile B64'!$Z10*Graph!$D$8 -> 16646160640 | C3: ='Kernel profile B64'!$R10*32+('Kernel profile B64'!$S10-'Kernel profile B64'!$R10)*64 -> 33300792832 | D3: =('Kernel profile B64'!$AC10-'Kernel profile B64'!$AB10)/1000000000 -> 0.061102 | E3: =B3/D3/1000000000 -> 272.43234 | F3: =B3/C3 -> 0.4998728 | G3: =1/F3 -> 2.0005089 | H3: =Graph!$B$5*(SUM('Kernel profile B32'!$V10:$W10,'Kernel profile B32'!$Y10)+2*'Kernel profile B32'!$X10)+'Kernel profile B32'!$Z10*Graph!$E$8 -> 8805756698624 | I3: ='Kernel profile B32'!$R10*32+('Kernel profile B32'!$S10-'Kernel profile B32'!$R10)*64 -> 529728 | J3: =('Kernel profile B32'!$AC10-'Kernel profile B32'!$AB10)/1000000000 -> 0.45817673 | K3: =H3/J3/1000000000 -> 19219.127 | L3: =H3/I3 -> 16623166 | M3: =1/L3 -> 6.0157011e-08
B4: =Graph!$B$5*(SUM('Kernel profile B64'!$V11:$W11,'Kernel profile B64'!$Y11)+2*'Kernel profile B64'!$X11)+'Kernel profile B64'!$Z11*Graph!$D$8 -> 0 | C4: ='Kernel profile B64'!$R11*32+('Kernel profile B64'!$S11-'Kernel profile B64'!$R11)*64 -> 0 | D4: =('Kernel profile B64'!$AC11-'Kernel profile B64'!$AB11)/1000000000 -> 0 | E4: =B4/D4/1000000000 -> #DIV/0! | F4: =B4/C4 -> #DIV/0! | G4: =1/F4 -> #DIV/0! | H4: =Graph!$B$5*(SUM('Kernel profile B32'!$V11:$W11,'Kernel profile B32'!$Y11)+2*'Kernel profile B32'!$X11)+'Kernel profile B32'!$Z11*Graph!$E$8 -> 0 | I4: ='Kernel profile B32'!$R11*32+('Kernel profile B32'!$S11-'Kernel profile B32'!$R11)*64 -> 0 | J4: =('Kernel profile B32'!$AC11-'Kernel profile B32'!$AB11)/1000000000 -> 0 | K4: =H4/J4/1000000000 -> #DIV/0! | L4: =H4/I4 -> #DIV/0! | M4: =1/L4 -> #DIV/0!
B5: =Graph!$B$5*(SUM('Kernel profile B64'!$V12:$W12,'Kernel profile B64'!$Y12)+2*'Kernel profile B64'!$X12)+'Kernel profile B64'!$Z12*Graph!$D$8 -> 0 | C5: ='Kernel profile B64'!$R12*32+('Kernel profile B64'!$S12-'Kernel profile B64'!$R12)*64 -> 0 | D5: =('Kernel profile B64'!$AC12-'Kernel profile B64'!$AB12)/1000000000 -> 0 | E5: =B5/D5/1000000000 -> #DIV/0! | F5: =B5/C5 -> #DIV/0! | G5: =1/F5 -> #DIV/0! | H5: =Graph!$B$5*(SUM('Kernel profile B32'!$V12:$W12,'Kernel profile B32'!$Y12)+2*'Kernel profile B32'!$X12)+'Kernel profile B32'!$Z12*Graph!$E$8 -> 0 | I5: ='Kernel profile B32'!$R12*32+('Kernel profile B32'!$S12-'Kernel profile B32'!$R12)*64 -> 0 | J5: =('Kernel profile B32'!$AC12-'Kernel profile B32'!$AB12)/1000000000 -> 0 | K5: =H5/J5/1000000000 -> #DIV/0! | L5: =H5/I5 -> #DIV/0! | M5: =1/L5 -> #DIV/0!
B6: =Graph!$B$5*(SUM('Kernel profile B64'!$V13:$W13,'Kernel profile B64'!$Y13)+2*'Kernel profile B64'!$X13)+'Kernel profile B64'!$Z13*Graph!$D$8 -> 0 | C6: ='Kernel profile B64'!$R13*32+('Kernel profile B64'!$S13-'Kernel profile B64'!$R13)*64 -> 0 | D6: =('Kernel profile B64'!$AC13-'Kernel profile B64'!$AB13)/1000000000 -> 0 | E6: =B6/D6/1000000000 -> #DIV/0! | F6: =B6/C6 -> #DIV/0! | G6: =1/F6 -> #DIV/0! | H6: =Graph!$B$5*(SUM('Kernel profile B32'!$V13:$W13,'Kernel profile B32'!$Y13)+2*'Kernel profile B32'!$X13)+'Kernel profile B32'!$Z13*Graph!$E$8 -> 0 | I6: ='Kernel profile B32'!$R13*32+('Kernel profile B32'!$S13-'Kernel profile B32'!$R13)*64 -> 0 | J6: =('Kernel profile B32'!$AC13-'Kernel profile B32'!$AB13)/1000000000 -> 0 | K6: =H6/J6/1000000000 -> #DIV/0! | L6: =H6/I6 -> #DIV/0! | M6: =1/L6 -> #DIV/0!
B7: =Graph!$B$5*(SUM('Kernel profile B64'!$V14:$W14,'Kernel profile B64'!$Y14)+2*'Kernel profile B64'!$X14)+'Kernel profile B64'!$Z14*Graph!$D$8 -> 0 | C7: ='Kernel profile B64'!$R14*32+('Kernel profile B64'!$S14-'Kernel profile B64'!$R14)*64 -> 0 | D7: =('Kernel profile B64'!$AC14-'Kernel profile B64'!$AB14)/1000000000 -> 0 | E7: =B7/D7/1000000000 -> #DIV/0! | F7: =B7/C7 -> #DIV/0! | G7: =1/F7 -> #DIV/0! | H7: =Graph!$B$5*(SUM('Kernel profile B32'!$V14:$W14,'Kernel profile B32'!$Y14)+2*'Kernel profile B32'!$X14)+'Kernel profile B32'!$Z14*Graph!$E$8 -> 0 | I7: ='Kernel profile B32'!$R14*32+('Kernel profile B32'!$S14-'Kernel profile B32'!$R14)*64 -> 0 | J7: =('Kernel profile B32'!$AC14-'Kernel profile B32'!$AB14)/1000000000 -> 0 | K7: =H7/J7/1000000000 -> #DIV/0! | L7: =H7/I7 -> #DIV/0! | M7: =1/L7 -> #DIV/0!
B8: =Graph!$B$5*(SUM('Kernel profile B64'!$V15:$W15,'Kernel profile B64'!$Y15)+2*'Kernel profile B64'!$X15)+'Kernel profile B64'!$Z15*Graph!$D$8 -> 0 | C8: ='Kernel profile B64'!$R15*32+('Kernel profile B64'!$S15-'Kernel profile B64'!$R15)*64 -> 0 | D8: =('Kernel profile B64'!$AC15-'Kernel profile B64'!$AB15)/1000000000 -> 0 | E8: =B8/D8/1000000000 -> #DIV/0! | F8: =B8/C8 -> #DIV/0! | G8: =1/F8 -> #DIV/0! | H8: =Graph!$B$5*(SUM('Kernel profile B32'!$V15:$W15,'Kernel profile B32'!$Y15)+2*'Kernel profile B32'!$X15)+'Kernel profile B32'!$Z15*Graph!$E$8 -> 0 | I8: ='Kernel profile B32'!$R15*32+('Kernel profile B32'!$S15-'Kernel profile B32'!$R15)*64 -> 0 | J8: =('Kernel profile B32'!$AC15-'Kernel profile B32'!$AB15)/1000000000 -> 0 | K8: =H8/J8/1000000000 -> #DIV/0! | L8: =H8/I8 -> #DIV/0! | M8: =1/L8 -> #DIV/0!
B9: =Graph!$B$5*(SUM('Kernel profile B64'!$V16:$W16,'Kernel profile B64'!$Y16)+2*'Kernel profile B64'!$X16)+'Kernel profile B64'!$Z16*Graph!$D$8 -> 0 | C9: ='Kernel profile B64'!$R16*32+('Kernel profile B64'!$S16-'Kernel profile B64'!$R16)*64 -> 0 | D9: =('Kernel profile B64'!$AC16-'Kernel profile B64'!$AB16)/1000000000 -> 0 | E9: =B9/D9/1000000000 -> #DIV/0! | F9: =B9/C9 -> #DIV/0! | G9: =1/F9 -> #DIV/0! | H9: =Graph!$B$5*(SUM('Kernel profile B32'!$V16:$W16,'Kernel profile B32'!$Y16)+2*'Kernel profile B32'!$X16)+'Kernel profile B32'!$Z16*Graph!$E$8 -> 0 | I9: ='Kernel profile B32'!$R16*32+('Kernel profile B32'!$S16-'Kernel profile B32'!$R16)*64 -> 0 | J9: =('Kernel profile B32'!$AC16-'Kernel profile B32'!$AB16)/1000000000 -> 0 | K9: =H9/J9/1000000000 -> #DIV/0! | L9: =H9/I9 -> #DIV/0! | M9: =1/L9 -> #DIV/0!
B10: =Graph!$B$5*(SUM('Kernel profile B64'!$V17:$W17,'Kernel profile B64'!$Y17)+2*'Kernel profile B64'!$X17)+'Kernel profile B64'!$Z17*Graph!$D$8 -> 0 | C10: ='Kernel profile B64'!$R17*32+('Kernel profile B64'!$S17-'Kernel profile B64'!$R17)*64 -> 0 | D10: =('Kernel profile B64'!$AC17-'Kernel profile B64'!$AB17)/1000000000 -> 0 | E10: =B10/D10/1000000000 -> #DIV/0! | F10: =B10/C10 -> #DIV/0! | G10: =1/F10 -> #DIV/0! | H10: =Graph!$B$5*(SUM('Kernel profile B32'!$V17:$W17,'Kernel profile B32'!$Y17)+2*'Kernel profile B32'!$X17)+'Kernel profile B32'!$Z17*Graph!$E$8 -> 0 | I10: ='Kernel profile B32'!$R17*32+('Kernel profile B32'!$S17-'Kernel profile B32'!$R17)*64 -> 0 | J10: =('Kernel profile B32'!$AC17-'Kernel profile B32'!$AB17)/1000000000 -> 0 | K10: =H10/J10/1000000000 -> #DIV/0! | L10: =H10/I10 -> #DIV/0! | M10: =1/L10 -> #DIV/0!
B11: =Graph!$B$5*(SUM('Kernel profile B64'!$V18:$W18,'Kernel profile B64'!$Y18)+2*'Kernel profile B64'!$X18)+'Kernel profile B64'!$Z18*Graph!$D$8 -> 0 | C11: ='Kernel profile B64'!$R18*32+('Kernel profile B64'!$S18-'Kernel profile B64'!$R18)*64 -> 0 | D11: =('Kernel profile B64'!$AC18-'Kernel profile B64'!$AB18)/1000000000 -> 0 | E11: =B11/D11/1000000000 -> #DIV/0! | F11: =B11/C11 -> #DIV/0! | G11: =1/F11 -> #DIV/0! | H11: =Graph!$B$5*(SUM('Kernel profile B32'!$V18:$W18,'Kernel profile B32'!$Y18)+2*'Kernel profile B32'!$X18)+'Kernel profile B32'!$Z18*Graph!$E$8 -> 0 | I11: ='Kernel profile B32'!$R18*32+('Kernel profile B32'!$S18-'Kernel profile B32'!$R18)*64 -> 0 | J11: =('Kernel profile B32'!$AC18-'Kernel profile B32'!$AB18)/1000000000 -> 0 | K11: =H11/J11/1000000000 -> #DIV/0! | L11: =H11/I11 -> #DIV/0! | M11: =1/L11 -> #DIV/0!
B12: =Graph!$B$5*(SUM('Kernel profile B64'!$V19:$W19,'Kernel profile B64'!$Y19)+2*'Kernel profile B64'!$X19)+'Kernel profile B64'!$Z19*Graph!$D$8 -> 0 | C12: ='Kernel profile B64'!$R19*32+('Kernel profile B64'!$S19-'Kernel profile B64'!$R19)*64 -> 0 | D12: =('Kernel profile B64'!$AC19-'Kernel profile B64'!$AB19)/1000000000 -> 0 | E12: =B12/D12/1000000000 -> #DIV/0! | F12: =B12/C12 -> #DIV/0! | G12: =1/F12 -> #DIV/0! | H12: =Graph!$B$5*(SUM('Kernel profile B32'!$V19:$W19,'Kernel profile B32'!$Y19)+2*'Kernel profile B32'!$X19)+'Kernel profile B32'!$Z19*Graph!$E$8 -> 0 | I12: ='Kernel profile B32'!$R19*32+('Kernel profile B32'!$S19-'Kernel profile B32'!$R19)*64 -> 0 | J12: =('Kernel profile B32'!$AC19-'Kernel profile B32'!$AB19)/1000000000 -> 0 | K12: =H12/J12/1000000000 -> #DIV/0! | L12: =H12/I12 -> #DIV/0! | M12: =1/L12 -> #DIV/0!
B13: =Graph!$B$5*(SUM('Kernel profile B64'!$V20:$W20,'Kernel profile B64'!$Y20)+2*'Kernel profile B64'!$X20)+'Kernel profile B64'!$Z20*Graph!$D$8 -> 0 | C13: ='Kernel profile B64'!$R20*32+('Kernel profile B64'!$S20-'Kernel profile B64'!$R20)*64 -> 0 | D13: =('Kernel profile B64'!$AC20-'Kernel profile B64'!$AB20)/1000000000 -> 0 | E13: =B13/D13/1000000000 -> #DIV/0! | F13: =B13/C13 -> #DIV/0! | G13: =1/F13 -> #DIV/0! | H13: =Graph!$B$5*(SUM('Kernel profile B32'!$V20:$W20,'Kernel profile B32'!$Y20)+2*'Kernel profile B32'!$X20)+'Kernel profile B32'!$Z20*Graph!$E$8 -> 0 | I13: ='Kernel profile B32'!$R20*32+('Kernel profile B32'!$S20-'Kernel profile B32'!$R20)*64 -> 0 | J13: =('Kernel profile B32'!$AC20-'Kernel profile B32'!$AB20)/1000000000 -> 0 | K13: =H13/J13/1000000000 -> #DIV/0! | L13: =H13/I13 -> #DIV/0! | M13: =1/L13 -> #DIV/0!
B14: =Graph!$B$5*(SUM('Kernel profile B64'!$V21:$W21,'Kernel profile B64'!$Y21)+2*'Kernel profile B64'!$X21)+'Kernel profile B64'!$Z21*Graph!$D$8 -> 0 | C14: ='Kernel profile B64'!$R21*32+('Kernel profile B64'!$S21-'Kernel profile B64'!$R21)*64 -> 0 | D14: =('Kernel profile B64'!$AC21-'Kernel profile B64'!$AB21)/1000000000 -> 0 | E14: =B14/D14/1000000000 -> #DIV/0! | F14: =B14/C14 -> #DIV/0! | G14: =1/F14 -> #DIV/0! | H14: =Graph!$B$5*(SUM('Kernel profile B32'!$V21:$W21,'Kernel profile B32'!$Y21)+2*'Kernel profile B32'!$X21)+'Kernel profile B32'!$Z21*Graph!$E$8 -> 0 | I14: ='Kernel profile B32'!$R21*32+('Kernel profile B32'!$S21-'Kernel profile B32'!$R21)*64 -> 0 | J14: =('Kernel profile B32'!$AC21-'Kernel profile B32'!$AB21)/1000000000 -> 0 | K14: =H14/J14/1000000000 -> #DIV/0! | L14: =H14/I14 -> #DIV/0! | M14: =1/L14 -> #DIV/0!
... B35: =Graph!$B$5*(SUM('Kernel profile B64'!$V42:$W42,'Kernel profile B64'!$Y42)+2*'Kernel profile B64'!$X42)+'Kernel profile B64'!$Z42*Graph!$D$8 -> 0 | C35: ='Kernel profile B64'!$R42*32+('Kernel profile B64'!$S42-'Kernel profile B64'!$R42)*64 -> 0 | D35: =('Kernel profile B64'!$AC42-'Kernel profile B64'!$AB42)/1000000000 -> 0 | E35: =B35/D35/1000000000 -> #DIV/0! | F35: =B35/C35 -> #DIV/0! | G35: =1/F35 -> #DIV/0! | H35: =Graph!$B$5*(SUM('Kernel profile B32'!$V42:$W42,'Kernel profile B32'!$Y42)+2*'Kernel profile B32'!$X42)+'Kernel profile B32'!$Z42*Graph!$E$8 -> 0 | I35: ='Kernel profile B32'!$R42*32+('Kernel profile B32'!$S42-'Kernel profile B32'!$R42)*64 -> 0 | J35: =('Kernel profile B32'!$AC42-'Kernel profile B32'!$AB42)/1000000000 -> 0 | K35: =H35/J35/1000000000 -> #DIV/0! | L35: =H35/I35 -> #DIV/0! | M35: =1/L35 -> #DIV/0!

Sheet Kernel profile B64
B1: gpu: 0 kernel : pmc : TCC_EA_RDREQ_32B_sum TCC_EA_RDREQ_sum TCC_EA_WRREQ_sum TCC_EA_WRREQ_64B_sum SQ_INSTS_VALU_ADD_F64 SQ_INSTS_VALU_MUL_F64 SQ_INSTS_VALU_FMA_F64 SQ_INSTS_VALU_TRANS_F64 SQ_INSTS_VALU_MFMA_MOPS_F64
B7: rocprof -i program_counters.txt --timestamp on -o "rocprof_logs_$(date +%s).csv" "${1}"
A9: Index | B9: KernelName | C9: gpu-id | D9: queue-id | E9: queue-index | F9: pid | G9: tid | H9: grd | I9: wgr | J9: lds | K9: scr | L9: arch_vgpr | M9: accum_vgpr | N9: sgpr | O9: wave_size | P9: sig | Q9: obj | R9: TCC_EA_RDREQ_32B_sum | S9: TCC_EA_RDREQ_sum | T9: TCC_EA_WRREQ_sum | U9: TCC_EA_WRREQ_64B_sum | V9: SQ_INSTS_VALU_ADD_F64 | W9: SQ_INSTS_VALU_MUL_F64 | X9: SQ_INSTS_VALU_FMA_F64 | Y9: SQ_INSTS_VALU_TRANS_F64 | Z9: SQ_INSTS_VALU_MFMA_MOPS_F64 | AA9: DispatchNs | AB9: BeginNs | AC9: EndNs | AD9: CompleteNs
A10: 0 | B10: __omp_offloading_84f0b5a2_fc00fd83__ZL4BurnjjPdS__l25_cce$noloop$form,kd | C10: 0 | D10: 0 | E10: 0 | F10: 2857959 | G10: 2857959 | H10: 4161540352 | I10: 256 | J10: 0 | K10: 0 | L10: 24 | M10: 0 | N10: 32 | O10: 64 | P10: 0x0 | Q10: 0x7f69542f8b80 | R10: 0 | S10: 520324888 | T10: 520452308 | U10: 520360306 | V10: 195072195 | W10: =65024065 -> 65024065 | X10: 0 | Y10: 0 | Z10: 0 | AA10: 1.3881233e+15 | AB10: 1.3879984e+15 | AC10: =AB10+61102*1000 -> 1.3879985e+15 | AD10: 1.3881234e+15

Sheet Kernel profile B32
B1: gpu: 0 kernel : pmc : TCC_EA_RDREQ_32B_sum TCC_EA_RDREQ_sum TCC_EA_WRREQ_sum TCC_EA_WRREQ_64B_sum SQ_INSTS_VALU_ADD_F32 SQ_INSTS_VALU_MUL_F32 SQ_INSTS_VALU_FMA_F32 SQ_INSTS_VALU_TRANS_F32 SQ_INSTS_VALU_MFMA_MOPS_F32
B7: rocprof -i program_counters.txt --timestamp on -o "rocprof_logs_$(date +%s).csv" "${1}"
A9: Index | B9: KernelName | C9: gpu-id | D9: queue-id | E9: queue-index | F9: pid | G9: tid | H9: grd | I9: wgr | J9: lds | K9: scr | L9: arch_vgpr | M9: accum_vgpr | N9: sgpr | O9: wave_size | P9: sig | Q9: obj | R9: TCC_EA_RDREQ_32B_sum | S9: TCC_EA_RDREQ_sum | T9: TCC_EA_WRREQ_sum | U9: TCC_EA_WRREQ_64B_sum | V9: SQ_INSTS_VALU_ADD_F32 | W9: SQ_INSTS_VALU_MUL_F32 | X9: SQ_INSTS_VALU_FMA_F32 | Y9: SQ_INSTS_VALU_TRANS_F32 | Z9: SQ_INSTS_VALU_MFMA_MOPS_F32 | AA9: DispatchNs | AB9: BeginNs | AC9: EndNs | AD9: CompleteNs
A10: 7 | B10: void Kokkos::Experimental::Impl::hip_parallel_launch_local_memory<Kokkos::Impl::ParallelFor<koliop::collision::State<koliop::collision::CollisionPolicy>::DoMultiply<Kokkos::Experimental::HIP, Kokkos::View<double**, Kokkos::Experimental::HIPSpace>, Kokkos::View<double*, Kokkos::Experimental::HIPSpace>, Kokkos::View<double*, Kokkos::Experimental::HIPSpace> >(Kokkos::Experimental::HIP const&, Kokkos::View<double**, Kokkos::Experimental::HIPSpace> const&, Kokkos::View<double*, Kokkos::Experimental::HIPSpace> const&, Kokkos::View<double*, Kokkos::Experimental::HIPSpace>&)::{lambda(int)#1}, Kokkos::RangePolicy<Kokkos::Experimental::HIP, Kokkos::Experimental::WorkItemProperty::ImplWorkItemProperty<0ul> >, Kokkos::Experimental::HIP>, 1024u, 1u>(Kokkos::Impl::ParallelFor<koliop::collision::State<koliop::collision::CollisionPolicy>::DoMultiply<Kokkos::Experimental::HIP, Kokkos::View<double**, Kokkos::Experimental::HIPSpace>, Kokkos::View<double*, Kokkos::Experimental::HIPSpace>, Kokkos::View<double*, Kokkos::Experimental::HIPSpace> >(Kokkos::Experimental::HIP const&, Kokkos::View<double**, Kokkos::Experimental::HIPSpace> const&, Kokkos::View<double*, Kokkos::Experimental::HIPSpace> const&, Kokkos::View<double*, Kokkos::Experimental::HIPSpace>&)::{lambda(int)#1}, Kokkos::RangePolicy<Kokkos::Experimental::HIP, Kokkos::Experimental::WorkItemProperty::ImplWorkItemProperty<0ul> >, Kokkos::Experimental::HIP> const*) [clone ,kd] | C10: 0 | D10: 1 | E10: 5 | F10: 2857278 | G10: 2857278 | H10: 1073741824 | I10: 1024 | J10: 0 | K10: 0 | L10: 28 | M10: 4 | N10: 32 | O10: 64 | P10: 0x0 | Q10: 0x7fe28d215e80 | R10: 0 | S10: 8277 | T10: 0 | U10: 0 | V10: 117440512 | W10: 16777216 | X10: 68719476736 | Y10: 16777216 | Z10: 0 | AA10: 1.387998e+15 | AB10: 1.387998e+15 | AC10: 1.3879984e+15 | AD10: 1.3879984e+15
